Workbook

Sheet Sayfa3
A1: BAYRAMPAŞA DEPODAKİ ELSAN AYRINTI DÖKÜMÜ
A3: 1.8 | C3: 2.2 | E3: 2.3 | G3: 2.45
A5: 2035.8 | C5: 2018.1 | E5: 2056.1 | G5: 1995.7
A37: =COUNT(A5:A35) -> 1 | C37: =COUNT(C5:C35) -> 1 | E37: =COUNT(E5:E35) -> 1 | G37: =COUNT(G5:G35) -> 1 | I37: =COUNT(I5:I35) -> 0 | K37: =COUNT(K5:K35) -> 0 | M37: =COUNT(M5:M35) -> 0 | O37: =COUNT(O5:O35) -> 0 | Q37: =COUNT(Q5:Q35) -> 0 | S37: =COUNT(S5:S35) -> 0 | U37: =COUNT(U5:U35) -> 0 | W37: =COUNT(W5:W35) -> 0 | Y37: =COUNT(Y5:Y35) -> 0 | AA37: =COUNT(AA5:AA35) -> 0 | AC37: =COUNT(AC5:AC35) -> 0
A38: =SUM(A5:A35) -> 2035.8 | C38: =SUM(C5:C35) -> 2018.1 | E38: =SUM(E5:E35) -> 2056.1 | G38: =SUM(G5:G35) -> 1995.7 | I38: =SUM(I5:I35) -> 0 | K38: =SUM(K5:K35) -> 0 | M38: =SUM(M5:M35) -> 0 | O38: =SUM(O5:O35) -> 0 | Q38: =SUM(Q5:Q35) -> 0 | S38: =SUM(S5:S35) -> 0 | U38: =SUM(U5:U35) -> 0 | W38: =SUM(W5:W35) -> 0 | Y38: =SUM(Y5:Y35) -> 0 | AA38: =SUM(AA5:AA35) -> 0 | AC38: =SUM(AC5:AC35) -> 0
A40: =SUM(A38:AC38) -> 8105.7

Sheet Sayfa4
A1: 0.2 | B1: 0.25 | C1: 0.3 | D1: 0.35 | E1: 0.4 | F1: 0.45 | G1: 0.5 | H1: 0.55 | I1: 0.6 | J1: 0.65 | K1: 0.7 | L1: 0.75 | M1: 0.8 | N1: 0.85 | O1: 0.9 | P1: 0.95 | Q1: 1 | R1: 1.05 | S1: 1.1 | T1: 1.15 | U1: 1.2 | V1: 1.25 | W1: 1.3 | X1: 1.35 | Y1: 1.4 | Z1: 1.45 | AA1: 1.5
A3: =SUM(A5:A15) -> 245.375 | B3: =SUM(B5:B24) -> 231.345 | C3: =SUM(C5:C14) -> 193.92 | D3: =SUM(D5:D10) -> 126.675 | E3: =SUM(E5:E10) -> 17.17 | F3: =SUM(F5:F21) -> 476.915 | G3: =SUM(G5:G24) -> 449.11 | H3: =SUM(H5:H19) -> 426.295 | I3: =SUM(I5:I38) -> 982.48 | J3: =SUM(J5:J22) -> 514.275 | K3: =SUM(K5:K18) -> 217.99 | L3: =SUM(L5:L19) -> 302.875 | M3: =SUM(M5:M16) -> 274.32 | N3: =SUM(N5:N14) -> 214.55 | O3: =SUM(O5:O15) -> 161.29 | P3: =SUM(P5:P21) -> 502.1 | Q3: =SUM(Q5:Q28) -> 629.92 | R3: =SUM(R5:R27) -> 519.805 | S3: =SUM(S5:S15) -> 228.25 | T3: =SUM(T5:T33) -> 790.9 | U3: =SUM(U5:U29) -> 754.175 | V3: =SUM(V5:V8) -> 85.9 | W3: =SUM(W5:W16) -> 281.41 | X3: =SUM(X5:X29) -> 790.85
A5: 3.015 | B5: 3.62 | C5: 7.83 | D5: 8.525 | E5: 8.565 | F5: 8.24 | G5: 8.19 | H5: 7.72 | I5: 7.11 | J5: 8.21 | K5: 7.09 | L5: 8.68 | M5: 8.205 | N5: 34.325 | O5: 8.64 | P5: 8.97 | Q5: 8.33 | R5: 8.385 | S5: 8.285 | T5: 7.98 | U5: 8.375 | V5: 8.205 | W5: 8.44 | X5: 8.505 | Y5: 8.2
A6: 7.53 | B6: 3.83 | C6: 7.77 | D6: 7.84 | E6: 8.605 | F6: 8.21 | G6: 8.2 | H6: 6.63 | I6: 7.52 | J6: 8.26 | K6: 7.17 | L6: 8.53 | M6: 8.305 | N6: 34.325 | O6: 8.65 | P6: 8.27 | Q6: 8.375 | R6: 8.435 | S6: 8.15 | T6: 7.55 | U6: 8.305 | V6: 8.345 | W6: 8.54 | X6: 8.55 | Y6: 8.1
A7: 7.54 | B7: 3.51 | C7: 30.6 | D7: 34.005 | F7: 34.615 | G7: 34.08 | H7: 33.89 | I7: 33.545 | J7: 34.03 | K7: 33.94 | L7: 33.435 | M7: 7.385 | N7: 34.49 | O7: 8.57 | P7: 34.1 | Q7: 33.61 | R7: 33.395 | S7: 8.36 | T7: 33.515 | U7: 34.34 | V7: 35.29 | W7: 8.71 | X7: 34.145 | Y7: 7.99
A8: 30.12 | B8: 3.48 | C8: 30.83 | D8: 33.935 | F8: 34.6 | G8: 34.055 | H8: 33.795 | I8: 33.45 | J8: 34.42 | K8: 34.38 | L8: 33.505 | M8: 8.405 | N8: 8.53 | O8: 8.32 | P8: 34.13 | Q8: 33.865 | R8: 33.26 | S8: 9.03 | T8: 33.425 | U8: 34.39 | V8: 34.06 | W8: 8.58 | X8: 31.33 | Y8: 8.29
A9: 30.07 | B9: 28.7 | C9: 31.96 | D9: 33.885 | F9: 34.6 | G9: 34.085 | H9: 33.79 | I9: 33.53 | J9: 34.365 | K9: 34.305 | L9: 33.48 | M9: 33.43 | N9: 8.53 | O9: 34.85 | P9: 34.185 | Q9: 33.835 | R9: 33.34 | S9: 34.025 | T9: 33.2 | U9: 34.315 | W9: 8.62 | X9: 34.145
A10: 26.64 | B10: 29.06 | C10: 30.84 | D10: 8.485 | F10: 34.595 | G10: 34.085 | H10: 33.82 | I10: 33.51 | J10: 34.45 | K10: 34.35 | L10: 33.405 | M10: 33.56 | N10: 8.57 | O10: 32.66 | P10: 34.175 | Q10: 33.595 | R10: 33.39 | S10: 33.93 | T10: 33.48 | U10: 34.285 | W10: 34.14 | X10: 34.17
A11: 30.19 | B11: 28.22 | C11: 30.93 | F11: 34.66 | G11: 34.08 | H11: 33.885 | I11: 33.59 | J11: 34.49 | K11: 8.53 | L11: 33.91 | M11: 33.32 | N11: 8.64 | O11: 28.5 | P11: 34.065 | Q11: 33.58 | R11: 33.62 | S11: 33.85 | T11: 33.41 | U11: 34.51 | W11: 33.53 | X11: 34
A12: 30.13 | B12: 29.06 | C12: 7.72 | F12: 34.6 | G12: 34.05 | H12: 33.835 | I12: 33.56 | J12: 34.425 | K12: 8.32 | L12: 33.45 | M12: 28.93 | N12: 8.63 | O12: 7.1 | P12: 34.1 | Q12: 33.67 | R12: 33.56 | S12: 33.395 | T12: 32.14 | U12: 34.38 | W12: 33.42 | X12: 34.125
A13: 19.92 | B13: 28.8 | C13: 7.73 | F13: 34.74 | G13: 34.12 | H13: 33.86 | I13: 33.525 | J13: 34.39 | K13: 8.27 | L13: 33.57 | M13: 28.52 | N13: 34.34 | O13: 7.11 | P13: 33.98 | Q13: 8.5 | R13: 33.345 | S13: 33.48 | T13: 33.435 | U13: 33.14 | W13: 33.51 | X13: 33.92
A14: 30.15 | B14: 26.92 | C14: 7.71 | F14: 34.53 | G14: 34.115 | H14: 33.85 | I14: 33.49 | J14: 34.38 | K14: 7.34 | L14: 8.355 | M14: 27.96 | N14: 34.17 | O14: 8.32 | P14: 33.97 | Q14: 8.38 | R14: 33.455 | S14: 17.37 | T14: 33.19 | U14: 34.425 | W14: 35.08 | X14: 34.165
A15: 30.07 | B15: 3.73 | F15: 34.49 | G15: 34.035 | H15: 33.82 | I15: 33.53 | J15: 34.505 | K15: 8.54 | L15: 8.355 | M15: 28.22 | O15: 8.57 | P15: 33.9 | Q15: 32.28 | R15: 33.435 | S15: 8.375 | T15: 33.445 | U15: 34.505 | W15: 33.83 | X15: 34.08
B16: 3.66 | F16: 34.57 | G16: 34.09 | H16: 33.88 | I16: 33.59 | J16: 34.48 | K16: 8.58 | L16: 8.36 | M16: 28.08 | P16: 33.81 | Q16: 33.66 | R16: 33.255 | T16: 33.455 | U16: 34.49 | W16: 35.01 | X16: 33.925
B17: 3.69 | F17: 34.645 | G17: 34.04 | H17: 33.805 | I17: 33.49 | J17: 34.45 | K17: 8.595 | L17: 9.85 | P17: 33.935 | Q17: 33.79 | R17: 33.22 | T17: 33.155 | U17: 34.47 | X17: 33.985
B18: 3.6 | F18: 34.59 | G18: 8.51 | H18: 33.92 | I18: 33.7 | J18: 33.47 | K18: 8.58 | L18: 8.53 | P18: 8.58 | Q18: 33.775 | R18: 33.41 | T18: 33.25 | U18: 34.455 | X18: 34.305
B19: 3.4 | F19: 29.08 | G19: 8.515 | H19: 5.795 | I19: 33.705 | J19: 34.405 | L19: 7.46 | P19: 34.57 | Q19: 33.81 | R19: 8.385 | T19: 33.175 | U19: 34.48 | X19: 34.12
B20: 3.5 | F20: 7.88 | G20: 8.19 | I20: 33.46 | J20: 34.465 | P20: 34.8 | Q20: 33.78 | R20: 8.315 | T20: 33.315 | U20: 34.56 | X20: 34.32
B21: 3.63 | F21: 8.27 | G21: 8.17 | I21: 33.665 | J21: 8.31 | P21: 32.56 | Q21: 33.205 | R21: 8.61 | T21: 33.375 | U21: 34.6 | X21: 34.31
B22: 6.41 | G22: 8.14 | I22: 33.68 | J22: 8.77 | Q22: 33.825 | R22: 8.73 | T22: 33.545 | U22: 34.31 | X22: 33.955
B23: 7.07 | G23: 8.19 | I23: 33.7 | Q23: 33.37 | R23: 8.58 | T23: 8.285 | U23: 34.525 | X23: 34.18
B24: 7.455 | G24: 8.17 | I24: 33.77 | Q24: 33.905 | R24: 34.5 | T24: 8.41 | U24: 34.435 | X24: 34.165
I25: 3.85 | Q25: 33.75 | R25: 8.23 | T25: 8.64 | U25: 34.47 | X25: 34.17
I26: 33.74 | Q26: 8.345 | R26: 8.79 | T26: 9.05 | U26: 34.425 | X26: 25.705
I27: 33.605 | Q27: 8.16 | R27: 8.16 | T27: 8.31 | U27: 34.445 | X27: 34.255
I28: 33.57 | Q28: 8.525 | T28: 33.495 | U28: 7.83 | X28: 34.195
I29: 33.515 | T29: 33.395 | U29: 7.71 | X29: 34.125
I30: 33.53 | T30: 33.335
I31: 33.48 | T31: 33.235
I32: 33.545 | T32: 33.385
I33: 33.525 | T33: 33.32
I34: 33.555
I35: 33.5
I36: 7.13
I37: 8.375
I38: 8.44

Sheet Sayfa5

Sheet TABLO
A1: STOK
A2: ÇIPLAK TEL | D2: RAF NO | E2: TOPLAM | F2: ELSAN | G2: HES | H2: ERİKOĞLU | I2: EMSAN | J2: KAVİ | K2: EMTEL
A3: 0.4 | B3: K160 | D3: 102 | E3: =SUM(F3:K3) -> 25.675 | K3: ='STOK DETAY'!D6 -> 25.675
A4: 0.5 | B4: K160 | D4: 102 | E4: =SUM(F4:K4) -> 0 | K4: ='STOK DETAY'!E6 -> 0
A5: 0.6 | B5: K160 | D5: 102 | E5: =SUM(F5:K5) -> 0 | K5: ='STOK DETAY'!F6 -> 0
A6: 2.6 | B6: K160 | E6: =SUM(F6:K6) -> 0 | K6: ='STOK DETAY'!G6 -> 0
A7: TOPLAM | E7: =SUM(F7:K7) -> 25.675 | F7: =SUM(F3:F6) -> 0 | G7: =SUM(G3:G6) -> 0 | H7: =SUM(H3:H6) -> 0 | I7: =SUM(I3:I6) -> 0 | J7: =SUM(J3:J6) -> 0 | K7: =SUM(K3:K6) -> 25.675
A8: HCO | D8: RAF NO | E8: TOPLAM | F8: ELSAN | G8: HES | H8: ERİKOĞLU | I8: EMSAN | J8: KAVİ | K8: EMTEL
A9: 0.1 | B9: K160 | C9: HCO | D9: 312 | E9: =SUM(F9:K9) -> 92.75 | H9: ='STOK DETAY'!H6 -> 92.75
A10: 0.16 | B10: K200 | C10: HCO | D10: 113 | E10: =SUM(F10:K10) -> 38.11 | H10: ='STOK DETAY'!I6 -> 38.11
A11: 0.2 | B11: K160 | C11: HCO | D11: 103 | E11: =SUM(F11:K11) -> 0 | G11: ='STOK DETAY'!L6 -> 0 | H11: ='STOK DETAY'!M6 -> 0
A12: 0.25 | B12: K160 | C12: HCO | D12: 103 | E12: =SUM(F12:K12) -> 8.615 | F12: ='STOK DETAY'!N6 -> 0 | G12: ='STOK DETAY'!O6 -> 8.615 | H12: ='STOK DETAY'!P6 -> 0 | J12: ='STOK DETAY'!Q6 -> 0 | K12: ='STOK DETAY'!R6 -> 0
A13: 0.28 | B13: A250 | C13: HCI | E13: =SUM(F13:K13) -> 93.21 | H13: ='STOK DETAY'!S6 -> 93.21
A14: 0.3 | B14: K160 | C14: HCO | D14: 201 | E14: =SUM(F14:K14) -> 54.595 | F14: ='STOK DETAY'!T6 -> 0 | G14: ='STOK DETAY'!U6 -> 0 | H14: ='STOK DETAY'!V6 -> 54.595 | K14: ='STOK DETAY'!W6 -> 0
A15: 0.35 | B15: K160 | C15: HCO | D15: 201 | E15: =SUM(F15:K15) -> 8.355 | F15: ='STOK DETAY'!X6 -> 0 | G15: ='STOK DETAY'!Y6 -> 0 | H15: ='STOK DETAY'!Z6 -> 8.355
A16: 0.4 | B16: K160 | C16: HCO | D16: 202 | E16: =SUM(F16:K16) -> 0 | F16: ='STOK DETAY'!AA6 -> 0 | G16: ='STOK DETAY'!AB6 -> 0 | H16: ='STOK DETAY'!AC6 -> 0 | K16: ='STOK DETAY'!AD6 -> 0
A17: 0.45 | B17: K160 | C17: HCO | D17: 202 | E17: =SUM(F17:K17) -> 0 | F17: ='STOK DETAY'!AE6 -> 0 | G17: ='STOK DETAY'!AF6 -> 0 | H17: ='STOK DETAY'!AG6 -> 0 | I17: ='STOK DETAY'!AH6 -> 0 | J17: ='STOK DETAY'!AI6 -> 0 | K17: ='STOK DETAY'!AJ6 -> 0
A18: 0.475 | B18: K160 | C18: HCO | E18: =SUM(F18:K18) -> 24.27 | H18: ='STOK DETAY'!AK6 -> 24.27
A19: 0.5 | B19: K160 | C19: HCO | D19: 203 | E19: =SUM(F19:K19) -> 0 | F19: ='STOK DETAY'!AL6 -> 0 | G19: ='STOK DETAY'!AM6 -> 0 | H19: ='STOK DETAY'!AN6 -> 0 | J19: ='STOK DETAY'!AO6 -> 0
A20: 0.55 | B20: K160 | C20: HCO | D20: 203 | E20: =SUM(F20:K20) -> 0 | F20: ='STOK DETAY'!AP6 -> 0 | G20: ='STOK DETAY'!AQ6 -> 0 | H20: ='STOK DETAY'!AR6 -> 0 | I20: ='STOK DETAY'!AS6 -> 0 | J20: ='STOK DETAY'!AT6 -> 0
A21: 0.6 | B21: K160 | C21: HCO | D21: 301 | E21: =SUM(F21:K21) -> 17 | F21: ='STOK DETAY'!AU6 -> 0 | G21: ='STOK DETAY'!AV6 -> 0 | H21: ='STOK DETAY'!AW6 -> 0 | I21: ='STOK DETAY'!AX6 -> 0 | J21: ='STOK DETAY'!AY6 -> 0 | K21: ='STOK DETAY'!AZ6 -> 17
A22: 0.65 | B22: K160 | C22: HCO | D22: 301 | E22: =SUM(F22:K22) -> 8.565 | F22: ='STOK DETAY'!BA6 -> 0 | G22: ='STOK DETAY'!BB6 -> 0 | H22: ='STOK DETAY'!BC6 -> 0 | J22: ='STOK DETAY'!BE6 -> 0 | K22: ='STOK DETAY'!BF6 -> 8.565
A23: 0.7 | B23: K160 | C23: HCO | D23: 302 | E23: =SUM(F23:K23) -> 34.685 | F23: ='STOK DETAY'!BG6 -> 0 | G23: ='STOK DETAY'!BH6 -> 0 | H23: ='STOK DETAY'!BI6 -> 0 | I23: ='STOK DETAY'!BJ6 -> 0 | J23: ='STOK DETAY'!BK6 -> 0 | K23: ='STOK DETAY'!BL6 -> 34.685
A24: 0.75 | B24: K160 | C24: HCO | D24: 302 | E24: =SUM(F24:K24) -> 42.745 | F24: ='STOK DETAY'!BM6 -> 0 | G24: ='STOK DETAY'!BN6 -> 0 | H24: ='STOK DETAY'!BO6 -> 0 | I24: ='STOK DETAY'!BP6 -> 0 | J24: ='STOK DETAY'!BQ6 -> 0 | K24: ='STOK DETAY'!BR6 -> 42.745
A25: 0.8 | B25: K160 | C25: HCO | D25: 303 | E25: =SUM(F25:K25) -> 53.14 | F25: ='STOK DETAY'!BS6 -> 0 | G25: ='STOK DETAY'!BT6 -> 0 | H25: ='STOK DETAY'!BU6 -> 0 | I25: ='STOK DETAY'!BV6 -> 0 | J25: ='STOK DETAY'!BW6 -> 0 | K25: ='STOK DETAY'!BX6 -> 53.14
A26: 0.85 | B26: K160 | C26: HCO | D26: 303 | E26: =SUM(F26:K26) -> 49.975 | F26: ='STOK DETAY'!BY6 -> 0 | G26: ='STOK DETAY'!BZ6 -> 0 | H26: ='STOK DETAY'!CA6 -> 0 | I26: ='STOK DETAY'!CB6 -> 0 | J26: ='STOK DETAY'!CC6 -> 0 | K26: ='STOK DETAY'!CD6 -> 49.975
A27: 0.9 | B27: K160 | C27: HCO | D27: 401 | E27: =SUM(F27:K27) -> 50.62 | F27: ='STOK DETAY'!CE6 -> 0 | G27: ='STOK DETAY'!CF6 -> 0 | H27: ='STOK DETAY'!CG6 -> 0 | I27: ='STOK DETAY'!CH6 -> 0 | J27: ='STOK DETAY'!CI6 -> 0 | K27: ='STOK DETAY'!CJ6 -> 50.62
A28: 0.95 | B28: K160 | C28: HCO | D28: 401 | E28: =SUM(F28:K28) -> 25.345 | F28: ='STOK DETAY'!CK6 -> 0 | G28: ='STOK DETAY'!CL6 -> 8.645 | H28: ='STOK DETAY'!CM6 -> 0 | I28: ='STOK DETAY'!CN6 -> 0 | J28: ='STOK DETAY'!CO6 -> 0 | K28: ='STOK DETAY'!CP6 -> 16.7
A29: 1 | B29: K160 | C29: HCO | D29: 402 | E29: =SUM(F29:K29) -> 24.93 | F29: ='STOK DETAY'!CQ6 -> 0 | G29: ='STOK DETAY'!CR6 -> 0 | H29: ='STOK DETAY'!CS6 -> 24.93 | I29: ='STOK DETAY'!CT6 -> 0 | J29: ='STOK DETAY'!CU6 -> 0 | K29: ='STOK DETAY'!CV6 -> 0
A30: 1.05 | B30: K160 | C30: HCO | D30: 402 | E30: =SUM(F30:K30) -> 0 | F30: ='STOK DETAY'!CW6 -> 0 | G30: ='STOK DETAY'!CX6 -> 0 | H30: ='STOK DETAY'!CY6 -> 0 | I30: ='STOK DETAY'!CZ6 -> 0 | J30: ='STOK DETAY'!DA6 -> 0 | K30: ='STOK DETAY'!DB6 -> 0
A31: 1.1 | B31: K160 | C31: HCO | D31: 403 | E31: =SUM(F31:K31) -> 25.735 | F31: ='STOK DETAY'!DC6 -> 0 | G31: ='STOK DETAY'!DD6 -> 0 | H31: ='STOK DETAY'!DE6 -> 25.735 | I31: ='STOK DETAY'!DF6 -> 0 | J31: ='STOK DETAY'!DG6 -> 0
A32: 1.15 | B32: K160 | C32: HCO | D32: 403 | E32: =SUM(F32:K32) -> 0 | F32: ='STOK DETAY'!DI6 -> 0 | G32: ='STOK DETAY'!DJ6 -> 0 | H32: ='STOK DETAY'!DK6 -> 0 | I32: ='STOK DETAY'!DL6 -> 0 | J32: ='STOK DETAY'!DM6 -> 0
A33: 1.2 | B33: K160 | C33: HCO | D33: 501 | E33: =SUM(F33:K33) -> 17.33 | F33: ='STOK DETAY'!DN6 -> 0 | G33: ='STOK DETAY'!DO6 -> 8.525 | H33: ='STOK DETAY'!DP6 -> 8.805 | I33: ='STOK DETAY'!DQ6 -> 0 | J33: ='STOK DETAY'!DR6 -> 0
A34: 1.25 | B34: K160 | C34: HCO | D34: 501 | E34: =SUM(F34:K34) -> 0 | F34: ='STOK DETAY'!DS6 -> 0 | G34: ='STOK DETAY'!DT6 -> 0 | H34: ='STOK DETAY'!DU6 -> 0 | I34: ='STOK DETAY'!DV6 -> 0 | J34: ='STOK DETAY'!DW6 -> 0 | K34: ='STOK DETAY'!DX6 -> 0
A35: 1.3 | B35: K160 | C35: HCO | D35: 502 | E35: =SUM(F35:K35) -> 8.38 | F35: ='STOK DETAY'!DY6 -> 0 | G35: ='STOK DETAY'!DZ6 -> 0 | H35: ='STOK DETAY'!EA6 -> 8.38 | I35: ='STOK DETAY'!EB6 -> 0 | J35: ='STOK DETAY'!EC6 -> 0 | K35: ='STOK DETAY'!ED6 -> 0
A36: 1.35 | B36: K160 | C36: HCO | D36: 502 | E36: =SUM(F36:K36) -> 388.52 | F36: ='STOK DETAY'!EE6 -> 0 | G36: ='STOK DETAY'!EF6 -> 0 | H36: ='STOK DETAY'!EG6 -> 378.33 | I36: ='STOK DETAY'!EH6 -> 1.75 | J36: ='STOK DETAY'!EI6 -> 8.44
A37: 1.4 | B37: K160 | C37: HCO | D37: 503 | E37: =SUM(F37:K37) -> 68.8 | F37: ='STOK DETAY'!EJ6 -> 0 | G37: ='STOK DETAY'!EK6 -> 0 | H37: ='STOK DETAY'!EL6 -> 0 | J37: ='STOK DETAY'!EM6 -> 68.8
A38: 1.45 | B38: K160 | C38: HCO | D38: 503 | E38: =SUM(F38:K38) -> 16.17 | F38: ='STOK DETAY'!EN6 -> 0 | G38: ='STOK DETAY'!EO6 -> 0 | H38: ='STOK DETAY'!EP6 -> 16.17 | J38: ='STOK DETAY'!EQ6 -> 0
A39: 1.5 | B39: K160 | C39: HCO | E39: =SUM(F39:K39) -> 0 | F39: ='STOK DETAY'!ER6 -> 0 | G39: ='STOK DETAY'!ES6 -> 0 | H39: ='STOK DETAY'!ET6 -> 0 | J39: ='STOK DETAY'!EU6 -> 0
A40: 1.55 | B40: K200 | C40: HCO | D40: 211 | E40: =SUM(F40:K40) -> 27.65 | J40: ='STOK DETAY'!EV6 -> 27.65
...

Sheet STOK DETAY
A1: STOK | C1: MARKA | D1: EMTEL | E1: EMTEL | F1: EMTEL | G1: EMTEL | H1: ERİKOĞLU | I1: ERİKOĞLU | J1: ERİKOĞLU | K1: ELSAN | L1: HES | M1: ERİKOĞLU | N1: ELSAN | O1: HES | P1: ERİKOĞLU | Q1: KAVİ | R1: EMTEL | S1: ERİKOĞLU | T1: ELSAN | U1: HES | V1: ERİKOĞLU | W1: EMTEL | X1: ELSAN | Y1: HES | Z1: ERİKOĞLU | AA1: ELSAN | AB1: HES | AC1: ERİKOĞLU | AD1: EMTEL | AE1: ELSAN | AF1: HES | AG1: ERİKOĞLU | AH1: EMSAN | AI1: KAVİ | AJ1: EMTEL | AK1: SUNKA | AL1: ELSAN | AM1: HES | AN1: ERİKOĞLU | AO1: KAVİ | AP1: ELSAN | AQ1: HES | AR1: ERİKOĞLU | AS1: EMSAN | AT1: KAVİ | AU1: ELSAN | AV1: HES | AW1: ERİKOĞLU | AX1: EMSAN | AY1: KAVİ | AZ1: EMTEL | BA1: ELSAN | BB1: HES | BC1: ERİKOĞLU | BD1: EMSAN | BE1: KAVİ | BF1: EMTEL | BG1: ELSAN | BH1: HES | BI1: ERİKOĞLU | BJ1: EMSAN | BK1: KAVİ | BL1: EMTEL | BM1: ELSAN | BN1: HES | BO1: ERİKOĞLU | BP1: EMSAN | BQ1: KAVİ | BR1: EMTEL | BS1: ELSAN | BT1: HES | BU1: ERİKOĞLU | BV1: EMSAN | BW1: KAVİ | BX1: EMTEL | BY1: ELSAN | BZ1: HES | CA1: ERİKOĞLU | CB1: EMSAN | CC1: KAVİ | CD1: EMTEL | CE1: ELSAN | CF1: HES | CG1: ERİKOĞLU | CH1: EMSAN | CI1: KAVİ | CJ1: EMTEL | CK1: ELSAN | CL1: HES | CM1: ERİKOĞLU | CN1: EMSAN | CO1: KAVİ | CP1: EMTEL | CQ1: ELSAN | CR1: HES | CS1: ERİKOĞLU | CT1: EMSAN | CU1: KAVİ | CV1: EMTEL | CW1: ELSAN | CX1: HES | CY1: ERİKOĞLU | CZ1: EMSAN | DA1: KAVİ | DB1: EMTEL | DC1: ELSAN | DD1: HES | DE1: ERİKOĞLU | DF1: EMSAN | DG1: KAVİ | DH1: EMTEL | DI1: ELSAN | DJ1: HES | DK1: ERİKOĞLU | DL1: EMSAN | DM1: KAVİ | DN1: ELSAN | DO1: HES | DP1: ERİKOĞLU | DQ1: EMSAN | DR1: KAVİ | DS1: ELSAN | DT1: HES | DU1: ERİKOĞLU | DV1: EMSAN | DW1: KAVİ | DX1: EMTEL | DY1: ELSAN | DZ1: HES | EA1: ERİKOĞLU | EB1: EMSAN | EC1: KAVİ | ED1: EMTEL | EE1: ELSAN | EF1: HES | EG1: ERİKOĞLU | EH1: EMSAN | EI1: KAVİ | EJ1: ELSAN | EK1: HES | EL1: ERİKOĞLU | EM1: KAVİ | EN1: ELSAN | EO1: HES | EP1: ERİKOĞLU | EQ1: KAVİ | ER1: ELSAN | ES1: HES | ET1: ERİKOĞLU | EU1: KAVİ | EV1: KAVİ | EW1: HES | EX1: KAVİ | EY1: HES | EZ1: ERİKOĞLU | FA1: ELSAN | FB1: HES | FC1: ERİKOĞLU | FD1: KAVİ | FE1: KAVİ | FF1: HES | FG1: ERİKOĞLU | FH1: KAVİ | FI1: ELSAN | FJ1: HES | FK1: ERİKOĞLU | FL1: KAVİ | FM1: ELSAN | FN1: KAVİ | FO1: KAVİ | FP1: KAVİ | FQ1: ELSAN | FR1: HES | FS1: ERİKOĞLU | FT1: EMTEL | FU1: HES | FV1: ERİKOĞLU | FW1: KAVİ | FX1: ELSAN | FY1: KAVİ | FZ1: EMTEL | GA1: HES | GB1: ERİKOĞLU | GC1: KAVİ | GD1: EMTEL | GE1: HES | GF1: KAVİ | GG1: KAVİ | GH1: ERİKOĞLU | GI1: KAVİ | GJ1: ELSAN | GK1: ERİKOĞLU | GL1: ELSAN | GM1: ERİKOĞLU | GN1: ERİKOĞLU | GO1: ERİKOĞLU | GP1: ELSAN | GQ1: ERİKOĞLU | GR1: ELSAN | GS1: ERİKOĞLU | GT1: ERİKOĞLU | GU1: ERİKOĞLU | GV1: ELSAN | GW1: ERİKOĞLU | GX1: ERİKOĞLU | GY1: ELSAN | GZ1: ERİKOĞLU | HA1: EMTEL | HB1: ELSAN | HC1: ELSAN | HD1: ERİKOĞLU | HE1: ELSAN | HF1: ERİKOĞLU | HG1: ELSAN | HH1: ERİKOĞLU | HI1: EMTEL | HJ1: ERİKOĞLU | HK1: ELSAN | HL1: ELSAN | HM1: ERİKOĞLU | HN1: EMTEL | HO1: ELSAN | HP1: ERİKOĞLU | HQ1: ELSAN | HR1: ERİKOĞLU | HS1: ELSAN | HT1: ERİKOĞLU | HU1: ELSAN | HV1: ERİKOĞLU | HW1: ELSAN | HX1: ERİKOĞLU | HY1: ELSAN | HZ1: ELSAN | IA1: ERİKOĞLU | IB1: ELSAN | IC1: ERİKOĞLU | ID1: ELSAN | IE1: ERİKOĞLU | IF1: ELSAN | IG1: ELSAN | IH1: ELSAN | II1: ERİKOĞLU | IJ1: ALM | IK1: ALM | IL1: ALM | IM1: ELSAN | IN1: ELSAN | IO1: EMTEL | IP1: ALM | IQ1: ALM | IR1: ALM | IS1: ALM | IT1: ALM | IU1: ALM | IV1: ALM | IW1: ALM
C2: MAKARA | D2: K160 | E2: K160 | F2: K160 | G2: K160 | H2: K160 | I2: K160 | J2: K160 | K2: K160 | L2: K160 | M2: K160 | N2: K160 | O2: K160 | P2: K160 | Q2: K160 | R2: K160 | S2: A250 | T2: K160 | U2: K160 | V2: K160 | W2: K160 | X2: K160 | Y2: K160 | Z2: K160 | AA2: K160 | AB2: K160 | AC2: K160 | AD2: K160 | AE2: K160 | AF2: K160 | AG2: K160 | AH2: K160 | AI2: K160 | AJ2: K160 | AK2: K160 | AL2: K160 | AM2: K160 | AN2: K160 | AO2: K160 | AP2: K160 | AQ2: K160 | AR2: K160 | AS2: K160 | AT2: K160 | AU2: K160 | AV2: K160 | AW2: K160 | AX2: K160 | AY2: K160 | AZ2: K160 | BA2: K160 | BB2: K160 | BC2: K160 | BD2: K160 | BE2: K160 | BF2: K160 | BG2: K160 | BH2: K160 | BI2: K160 | BJ2: K160 | BK2: K160 | BL2: K160 | BM2: K160 | BN2: K160 | BO2: K160 | BP2: K160 | BQ2: K160 | BR2: K160 | BS2: K160 | BT2: K160 | BU2: K160 | BV2: K160 | BW2: K160 | BX2: K160 | BY2: K160 | BZ2: K160 | CA2: K160 | CB2: K160 | CC2: K160 | CD2: K160 | CE2: K160 | CF2: K160 | CG2: K160 | CH2: K160 | CI2: K160 | CJ2: K160 | CK2: K160 | CL2: K160 | CM2: K160 | CN2: K160 | CO2: K160 | CP2: K160 | CQ2: K160 | CR2: K160 | CS2: K160 | CT2: K160 | CU2: K160 | CV2: K160 | CW2: K160 | CX2: K160 | CY2: K160 | CZ2: K160 | DA2: K160 | DB2: K160 | DC2: K160 | DD2: K160 | DE2: K160 | DF2: K160 | DG2: K160 | DH2: K160 | DI2: K160 | DJ2: K160 | DK2: K160 | DL2: K160 | DM2: K160 | DN2: K160 | DO2: K160 | DP2: K160 | DQ2: K160 | DR2: K160 | DS2: K160 | DT2: K160 | DU2: K160 | DV2: K160 | DW2: K160 | DX2: K160 | DY2: K160 | DZ2: K160 | EA2: K160 | EB2: K160 | EC2: K160 | ED2: K160 | EE2: K160 | EF2: K160 | EG2: K160 | EH2: K160 | EI2: K160 | EJ2: K160 | EK2: K160 | EL2: K160 | EM2: K160 | EN2: K160 | EO2: K160 | EP2: K160 | EQ2: K160 | ER2: K160 | ES2: K160 | ET2: K160 | EU2: K160 | EV2: K200 | EW2: K160 | EX2: K200 | EY2: K250 | EZ2: K250 | FA2: K250 | FB2: K250 | FC2: K250 | FD2: K250 | FE2: K200 | FF2: K250 | FG2: K250 | FH2: K250 | FI2: K250 | FJ2: K250 | FK2: K250 | FL2: K250 | FM2: K250 | FN2: K250 | FO2: K250 | FP2: K250 | FQ2: K250 | FR2: K250 | FS2: K250 | FT2: K250 | FU2: K250 | FV2: K250 | FW2: K250 | FX2: K250 | FY2: K250 | FZ2: K250 | GA2: K250 | GB2: K250 | GC2: K250 | GD2: K250 | GE2: K250 | GF2: K250 | GG2: K251 | GH2: K250 | GI2: K250 | GJ2: K160 | GK2: K160 | GL2: K160 | GM2: K160 | GN2: K160 | GO2: K160 | GP2: K160 | GQ2: K160 | GR2: K160 | GS2: K160 | GT2: K160 | GU2: K160 | GV2: K160 | GW2: K160 | GX2: K160 | GY2: K160 | GZ2: K160 | HA2: K160 | HB2: K160 | HC2: K160 | HD2: K160 | HE2: K160 | HF2: K160 | HG2: K160 | HH2: K160 | HI2: K160 | HJ2: K160 | HK2: K160 | HL2: K160 | HM2: K160 | HN2: K160 | HO2: K160 | HP2: K160 | HQ2: K160 | HR2: K160 | HS2: K160 | HT2: K160 | HU2: K160 | HV2: K160 | HW2: K160 | HX2: K160 | HY2: K160 | HZ2: K160 | IA2: K160 | IB2: K160 | IC2: K160 | ID2: K160 | IE2: K160 | IF2: K160 | IG2: K160 | IH2: K160 | II2: K160 | IJ2: ALM | IK2: ALM | IL2: ALM | IM2: A315 | IN2: A315 | IO2: A250 | IP2: ALM | IQ2: ALM | IR2: ALM | IS2: ALM | IT2: ALM | IU2: ALM | IV2: ALM | IW2: ALM
C3: CİNSİ | D3: ÇIPLAK TEL | E3: ÇIPLAK TEL | F3: ÇIPLAK TEL | G3: ÇIPLAK TEL | H3: HCO | I3: HCO | J3: HCI | K3: HCO | L3: HCO | M3: HCO | N3: HCO | O3: HCO | P3: HCO | Q3: HCO | R3: HCO | S3: HCI | T3: HCO | U3: HCO | V3: HCO | W3: HCO | X3: HCO | Y3: HCO | Z3: HCO | AA3: HCO | AB3: HCO | AC3: HCO | AD3: HCO | AE3: HCO | AF3: HCO | AG3: HCO | AH3: HCO | AI3: HCO | AJ3: HCO | AK3: HCO | AL3: HCO | AM3: HCO | AN3: HCO | AO3: HCO | AP3: HCO | AQ3: HCO | AR3: HCO | AS3: HCO | AT3: HCO | AU3: HCO | AV3: HCO | AW3: HCO | AX3: HCO | AY3: HCO | AZ3: HCO | BA3: HCO | BB3: HCO | BC3: HCO | BD3: HCO | BE3: HCO | BF3: HCO | BG3: HCO | BH3: HCO | BI3: HCO | BJ3: HCO | BK3: HCO | BL3: HCO | BM3: HCO | BN3: HCO | BO3: HCO | BP3: HCO | BQ3: HCO | BR3: HCO | BS3: HCO | BT3: HCO | BU3: HCO | BV3: HCO | BW3: HCO | BX3: HCO | BY3: HCO | BZ3: HCO | CA3: HCO | CB3: HCO | CC3: HCO | CD3: HCO | CE3: HCO | CF3: HCO | CG3: HCO | CH3: HCO | CI3: HCO | CJ3: HCO | CK3: HCO | CL3: HCO | CM3: HCO | CN3: HCO | CO3: HCO | CP3: HCO | CQ3: HCO | CR3: HCO | CS3: HCO | CT3: HCO | CU3: HCO | CV3: HCO | CW3: HCO | CX3: HCO | CY3: HCO | CZ3: HCO | DA3: HCO | DB3: HCO | DC3: HCO | DD3: HCO | DE3: HCO | DF3: HCO | DG3: HCO | DH3: HCO | DI3: HCO | DJ3: HCO | DK3: HCO | DL3: HCO | DM3: HCO | DN3: HCO | DO3: HCO | DP3: HCO | DQ3: HCO | DR3: HCO | DS3: HCO | DT3: HCO | DU3: HCO | DV3: HCO | DW3: HCO | DX3: HCO | DY3: HCO | DZ3: HCO | EA3: HCO | EB3: HCO | EC3: HCO | ED3: HCO | EE3: HCO | EF3: HCO | EG3: HCO | EH3: HCO | EI3: HCO | EJ3: HCO | EK3: HCO | EL3: HCO | EM3: HCO | EN3: HCO | EO3: HCO | EP3: HCO | EQ3: HCO | ER3: HCO | ES3: HCO | ET3: HCO | EU3: HCO | EV3: HCO | EW3: HCO | EX3: HCO | EY3: HCO | EZ3: HCO | FA3: HCO | FB3: HCO | FC3: HCO | FD3: HCO | FE3: HCO | FF3: HCO | FG3: HCO | FH3: HCO | FI3: HCO | FJ3: HCO | FK3: HCO | FL3: HCO | FM3: HCO | FN3: HCO | FO3: HCO | FP3: HCO | FQ3: HCO | FR3: HCO | FS3: HCO | FT3: HCO | FU3: HCO | FV3: HCO | FW3: HCO | FX3: HCO | FY3: HCO | FZ3: HCO | GA3: HCO | GB3: HCO | GC3: HCO | GD3: HCO | GE3: HCO | GF3: HCO | GG3: HCO | GH3: HCO | GI3: HCO | GJ3: LHI | GK3: LHI | GL3: LHI | GM3: LHI | GN3: LHI | GO3: LHI | GP3: LHI | GQ3: LHI | GR3: LHI | GS3: LHO | GT3: LHO | GU3: LHI | GV3: LHI | GW3: LHI | GX3: LHI | GY3: LHI | GZ3: LHI | HA3: LHI | HB3: LHI | HC3: LHI | HD3: LHI | HE3: LHI | HF3: LHI | HG3: LHI | HH3: LHI | HI3: LHI | HJ3: LHI | HK3: LHI | HL3: LHI | HM3: LHI | HN3: LHI | HO3: LHI | HP3: LHI | HQ3: LHI | HR3: LHI | HS3: LHI | HT3: LHO | HU3: LHI | HV3: LHI | HW3: LHI | HX3: LHI | HY3: LHI | HZ3: LHI | IA3: LHI | IB3: LHI | IC3: LHI | ID3: LHI | IE3: LHI | IF3: LHI | IG3: LHI | IH3: LHI | II3: LHI | IJ3: ALÜMİNYUM | IK3: ALÜMİNYUM | IL3: ALÜMİNYUM | IM3: ALÜMİNYUM | IN3: ALÜMİNYUM | IO3: ALÜMİNYUM | IP3: ALÜMİNYUM | IQ3: ALÜMİNYUM | IR3: ALÜMİNYUM | IS3: ALÜMİNYUM | IT3: ALÜMİNYUM | IU3: ALÜMİNYUM | IV3: ALÜMİNYUM | IW3: ALÜMİNYUM
C4: ÇAP | D4: 0.4 | E4: 0.5 | F4: 0.6 | G4: 2.6 | H4: 0.1 | I4: 0.16 | J4: 0.17 | K4: 0.2 | L4: 0.2 | M4: 0.2 | N4: 0.25 | O4: 0.25 | P4: 0.25 | Q4: 0.25 | R4: 0.25 | S4: 0.28 | T4: 0.3 | U4: 0.3 | V4: 0.3 | W4: 0.3 | X4: 0.35 | Y4: 0.35 | Z4: 0.35 | AA4: 0.4 | AB4: 0.4 | AC4: 0.4 | AD4: 0.4 | AE4: 0.45 | AF4: 0.45 | AG4: 0.45 | AH4: 0.45 | AI4: 0.45 | AJ4: 0.45 | AK4: 0.475 | AL4: 0.5 | AM4: 0.5 | AN4: 0.5 | AO4: 0.5 | AP4: 0.55 | AQ4: 0.55 | AR4: 0.55 | AS4: 0.55 | AT4: 0.55 | AU4: 0.6 | AV4: 0.6 | AW4: 0.6 | AX4: 0.6 | AY4: 0.6 | AZ4: 0.6 | BA4: 0.65 | BB4: 0.65 | BC4: 0.65 | BD4: 0.65 | BE4: 0.65 | BF4: 0.65 | BG4: 0.7 | BH4: 0.7 | BI4: 0.7 | BJ4: 0.7 | BK4: 0.7 | BL4: 0.7 | BM4: 0.75 | BN4: 0.75 | BO4: 0.75 | BP4: 0.75 | BQ4: 0.75 | BR4: 0.75 | BS4: 0.8 | BT4: 0.8 | BU4: 0.8 | BV4: 0.8 | BW4: 0.8 | BX4: 0.8 | BY4: 0.85 | BZ4: 0.85 | CA4: 0.85 | CB4: 0.85 | CC4: 0.85 | CD4: 0.85 | CE4: 0.9 | CF4: 0.9 | CG4: 0.9 | CH4: 0.9 | CI4: 0.9 | CJ4: 0.9 | CK4: 0.95 | CL4: 0.95 | CM4: 0.95 | CN4: 0.95 | CO4: 0.95 | CP4: 0.95 | CQ4: 1 | CR4: 1 | CS4: 1 | CT4: 1 | CU4: 1 | CV4: 1 | CW4: 1.05 | CX4: 1.05 | CY4: 1.05 | CZ4: 1.05 | DA4: 1.05 | DB4: 1.05 | DC4: 1.1 | DD4: 1.1 | DE4: 1.1 | DF4: 1.1 | DG4: 1.1 | DH4: 1.1 | DI4: 1.15 | DJ4: 1.15 | DK4: 1.15 | DL4: 1.15 | DM4: 1.15 | DN4: 1.2 | DO4: 1.2 | DP4: 1.2 | DQ4: 1.2 | DR4: 1.2 | DS4: 1.25 | DT4: 1.25 | DU4: 1.25 | DV4: 1.25 | DW4: 1.25 | DX4: 1.25 | DY4: 1.3 | DZ4: 1.3 | EA4: 1.3 | EB4: 1.3 | EC4: 1.3 | ED4: 1.3 | EE4: 1.35 | EF4: 1.35 | EG4: 1.35 | EH4: 1.35 | EI4: 1.35 | EJ4: 1.4 | EK4: 1.4 | EL4: 1.4 | EM4: 1.4 | EN4: 1.45 | EO4: 1.45 | EP4: 1.45 | EQ4: 1.45 | ER4: 1.5 | ES4: 1.5 | ET4: 1.5 | EU4: 1.5 | EV4: 1.55 | EW4: 1.6 | EX4: 1.65 | EY4: 1.7 | EZ4: 1.7 | FA4: 1.8 | FB4: 1.8 | FC4: 1.8 | FD4: 1.8 | FE4: 1.85 | FF4: 1.9 | FG4: 1.9 | FH4: 1.9 | FI4: 2 | FJ4: 2 | FK4: 2 | FL4: 2 | FM4: 2.2 | FN4: 2.2 | FO4: 2.3 | FP4: 2.4 | FQ4: 2.5 | FR4: 2.5 | FS4: 2.5 | FT4: 2.5 | FU4: 2.6 | FV4: 2.6 | FW4: 2.6 | FX4: 2.7 | FY4: 2.7 | FZ4: 2.7 | GA4: 3 | GB4: 3 | GC4: 3 | GD4: 3 | GE4: 3.2 | GF4: 3.2 | GG4: 3.5 | GH4: 3.65 | GI4: 4 | GJ4: 0.08 | GK4: 0.08 | GL4: 0.1 | GM4: 0.1 | GN4: 0.11 | GO4: 0.12 | GP4: 0.14 | GQ4: 0.14 | GR4: 0.15 | GS4: 0.15 | GT4: 0.16 | GU4: 0.17 | GV4: 0.18 | GW4: 0.18 | GX4: 0.19 | GY4: 0.2 | GZ4: 0.2 | HA4: 0.2 | HB4: 0.22 | HC4: 0.25 | HD4: 0.25 | HE4: 0.28 | HF4: 0.28 | HG4: 0.3 | HH4: 0.3 | HI4: 0.3 | HJ4: 0.32 | HK4: 0.33 | HL4: 0.35 | HM4: 0.35 | HN4: 0.35 | HO4: 0.38 | HP4: 0.38 | HQ4: 0.4 | HR4: 0.4 | HS4: 0.45 | HT4: 0.45 | HU4: 0.5 | HV4: 0.5 | HW4: 0.55 | HX4: 0.55 | HY4: 0.6 | HZ4: 0.65 | IA4: 0.65 | IB4: 0.7 | IC4: 0.7 | ID4: 0.75 | IE4: 0.75 | IF4: 0.8 | IG4: 0.85 | IH4: 0.9 | II4: 0.95 | IJ4: 0.3 | IK4: 0.5 | IL4: 0.55 | IM4: 0.6 | IN4: 0.7 | IO4: 0.7 | IP4: 1 | IQ4: 1.2 | IR4: 1.3 | IS4: 1.4 | IT4: 1.6 | IU4: 1.7 | IV4: 1.8 | IW4: 3.5
A6: TARİH | B6: CARİ | C6: =SUM(D6:IW6) -> 2793.263 | D6: =SUM(D8:D1048576) -> 25.675 | E6: =SUM(E8:E1048576) -> 0 | F6: =SUM(F8:F1048576) -> 0 | G6: =SUM(G8:G1048576) -> 0 | H6: =SUM(H8:H1048576) -> 92.75 | I6: =SUM(I8:I1048576) -> 38.11 | J6: =SUM(J8:J1048576) -> 0 | K6: =SUM(K8:K1048576) -> 0 | ... IW6: =SUM(IW8:IW1048576) -> 52.36
A8: 44316 | B8: DEVİR | C8: =SUM(I8:JT8) -> 27884.78 | K8: 453.3 | L8: 431.98 | O8: 254.86 | Q8: 21.62 | T8: 0 | U8: 689.545 | Y8: 775.635 | AB8: 33.975 | AD8: 31.38 | AE8: 195.66 | AF8: 42.65 | AH8: 7.28 | AI8: 7.88 | AL8: 8.5 | AM8: 309.17 | AO8: 44.15 | AP8: 352.52 | AQ8: 0 | AS8: 25.25 | AT8: 22.73 | AU8: 0 | AV8: 555.735 | AZ8: 17.08 | BA8: 121.93 | BB8: 0 | BF8: 22.81 | BG8: 8.43 | BL8: 42.34 | BM8: 76.82 | BN8: 34.105 | BR8: 49.48 | BS8: 375.55 | BT8: 8.51 | BX8: 0 | BY8: 662.91 | BZ8: 0 | CC8: =16.27-8.73 -> 7.54 | CE8: 365.38 | CF8: 0 | CJ8: 0 | CK8: 325.46 | CL8: 0 | CM8: 0 | CP8: 25.14 | CQ8: 494.4 | CR8: 34.085 | CT8: 7.85 | CV8: 16.54 | CW8: =446.93-8.67 -> 438.26 | CX8: 0 | CZ8: 9 | DB8: 30.71 | DC8: 467.51 | DD8: 0 | DF8: 7.58 | DG8: 75.26 | DI8: 42.84 | DJ8: 76.11 | DM8: 67.69 | DN8: 387.94 | DO8: 208.34 | DQ8: 25.23 | DR8: 31.1 | DS8: 98.03 | DT8: 408.02 | DV8: 32.38 | DW8: 57.84 | DY8: 32.49 | DZ8: 570.015 | EB8: 8.32 | EE8: 117.4 | EF8: 274.245 | EJ8: 509.01 | EK8: 17.035 | EN8: 479.62 | EO8: 446.36 | ES8: 574.555 | EW8: 973.295 | EY8: 628.275 | FB8: 129.72 | FF8: 902.885 | FJ8: 1112.62 | FQ8: 82.4 | FR8: 363.655 | FU8: 415.39 | FX8: 511.76 | GA8: 626.415 | GE8: 379.575 | GP8: 282.95 | GV8: 502.85 | GY8: 738.9 | HC8: 572.62 | HE8: 55.7 | HG8: 477.75 | HK8: 1270.42 | HL8: 675.14 | HO8: 472.64 | HP8: 77.68 | HQ8: 343.73 | HR8: -1 | HS8: 480.17 | HU8: 781.34 | HW8: 661.06 | HY8: 343 | HZ8: 555.38 | IB8: 155.1 | ID8: 333.43 | IF8: 414.78 | IG8: 112.08
A9: 44320 | B9: TRANS-EL | C9: =SUM(I9:JT9) -> 0
A10: 44320 | B10: ENDÜSTRİ ELEKTRİK | C10: =SUM(I10:JT10) -> -8.31 | CP10: -8.31
A11: 44320 | B11: EGOSAN | C11: =SUM(I11:JT11) -> -35.8 | GY11: -35.8
A12: 44320 | B12: SERİ BOBİNAJ | C12: =SUM(I12:JT12) -> -33.815 | O12: -8.49 | AM12: -8.25 | AV12: -17.075
A13: 44321 | B13: ELEKTRO-İŞ | C13: =SUM(I13:JT13) -> -34.3 | DN13: -34.3
A14: 44321 | B14: EGOSAN | C14: =SUM(I14:JT14) -> -52.06 | BA14: -8.79 | BG14: -8.43 | BM14: -8.77 | BT14: -8.27 | CQ14: -9.09 | CW14: -8.71
A15: 44321 | B15: HES | C15: =SUM(I15:JT15) -> 6039.39 | AB15: 505.34 | AF15: 500.26 | AM15: 501.77 | BH15: 1010.05 | BN15: 1004.44 | BT15: 499.99 | BZ15: 503.08 | CF15: 509.55 | CL15: 504.61 | CR15: 500.3
A16: 44322 | B16: YAVUZ-DÜKKAN | C16: =SUM(I16:JT16) -> -397.34 | AB16: -33.77 | AV16: -68.215 | BH16: -102.305 | BM16: -58.45 | BN16: -34 | DZ16: -100.6
A17: 44322 | B17: MEGA ELEKTRONİK | C17: =SUM(I17:JT17) -> -26.02 | IF17: -9.44 | IG17: -16.58
A18: 44322 | B18: İLAY | C18: =SUM(I18:JT18) -> -24.05 | BR18: -8.2 | DB18: -7.25 | DG18: -8.6
A19: 44322 | B19: ONUR | C19: =SUM(I19:JT19) -> -25.73 | BA19: -8.79 | BH19: -8.595 | BT19: -8.345
A20: 44322 | B20: SERİ BOBİNAJ | C20: =SUM(I20:JT20) -> -8.75 | BA20: -8.75
A21: 44323 | B21: MEGA ELEKTRONİK | C21: =SUM(I21:JT21) -> 18.5 | GY21: 18.5
A22: 44323 | B22: YAVUZ-DÜKKAN | C22: =SUM(I22:JT22) -> -133.64 | BZ22: -63.67 | DC22: -69.97
A23: 44323 | B23: MURAT HAYKIR | C23: =SUM(I23:JT23) -> -51.3 | BH23: -8.585 | BM23: -8.78 | BT23: -16.595 | BY23: -8.59 | CE23: -8.75
A24: 44326 | B24: YAVUZ-ÇEVİKLER | C24: =SUM(I24:JT24) -> -270.26 | BN24: -66.86 | BT24: -66.785 | BY24: -69.13 | CF24: -34.005 | CL24: -33.48
A25: 44326 | B25: YAVUZ-TEZCAN | C25: =SUM(I25:JT25) -> -375.465 | AP25: -32.31 | BA25: -34.82 | BH25: -33.605 | BN25: -33.48 | BS25: -34.9 | BZ25: -33.925 | CL25: -33.965 | CW25: -68.94 | DC25: -69.52
A26: 44326 | B26: YAVUZ-TURSAN | C26: =SUM(I26:JT26) -> -102.55 | BH26: -33.47 | BN26: -33.54 | BY26: -35.54
A27: 44327 | B27: KALDE | C27: =SUM(I27:JT27) -> -50.915 | BA27: -16.91 | BH27: -17.185 | BS27: -8.34 | BZ27: -8.48
A28: 44333 | B28: FLAŞ | C28: =SUM(I28:JT28) -> -375.34 | BS28: -70.02 | BY28: -68.47 | CE28: -69.6 | CK28: -64.76 | DC28: -70 | DY28: -32.49
A29: 44333 | B29: MÜMTAZ | C29: =SUM(I29:JT29) -> -875.605 | BH29: -99.47 | BN29: -234.44 | BT29: -100.005 | BZ29: -101.495 | CF29: -102.185 | CL29: -33.635 | CR29: -33.685 | CW29: -34.42 | DC29: -34.59 | DT29: -101.68
A30: 44333 | B30: ELSAN | C30: =SUM(I30:JT30) -> 522.38 | IG30: 522.38
A31: 44334 | B31: İLAY | C31: =SUM(I31:JT31) -> -24.08 | AO31: -8.19 | AT31: -7.58 | BL31: -8.31
A32: 44334 | B32: SİSTEM BOBİNAJ | C32: =SUM(I32:JT32) -> -17.54 | BM32: -8.79 | BT32: -8.75
A33: 44334 | B33: HES | C33: =SUM(I33:JT33) -> 5556.705 | O33: 511.46 | BB33: 1018.41 | BH33: 504.595 | BN33: 499.01 | BT33: 506.17 | CF33: 506.935 | CL33: 505.915 | CX33: 502.16 | DD33: 502.635 | DJ33: 499.415
A34: 44334 | B34: AYHAN | C34: =SUM(I34:JT34) -> -268.12 | BH34: -32.705 | BN34: -33.34 | BT34: -33.375 | BZ34: -33.745 | CR34: -67.555 | CX34: -33.725 | DT34: -33.675
A35: 44334 | B35: ŞANLI | C35: =SUM(I35:JT35) -> -200.835 | AP35: -32.28 | BB35: -33.965 | BH35: -33.695 | BT35: -33.285 | BZ35: -33.74 | CF35: -33.87
A36: 44334 | B36: PORT BOBİNAJ | C36: =SUM(I36:JT36) -> -243.85 | AM36: -16.84 | AP36: -15.61 | BA36: -35.08 | BH36: -32.84 | BS36: -34.57 | BY36: -34.49 | CK36: -14.58 | CR36: -8.1 | DJ36: -16.915 | EF36: -17.055 | EJ36: -17.77
A37: 44335 | B37: ŞANLI | C37: =SUM(I37:JT37) -> -137.055 | AV37: -34.185 | BN37: -33.25 | CW37: -34.5 | DN37: -35.12
A38: 44335 | B38: BİRSAN | C38: =SUM(I38:JT38) -> 0
A39: 44335 | B39: FİNAL | C39: =SUM(I39:JT39) -> -135.225 | AV39: -34.23 | BB39: -34.005 | BH39: -33.68 | BN39: -33.31
A40: 44335 | B40: FLAŞ | C40: =SUM(I40:JT40) -> -43.155 | FB40: -43.155
A41: 44335 | B41: YAVUZ-GÜLEN | C41: =SUM(I41:JT41) -> -168.755 | AF41: -33.485 | AV41: -34.275 | BB41: -33.955 | BH41: -33.585 | BT41: -33.455
A42: 44335 | B42: YAVUZ-DÜKKAN | C42: =SUM(I42:JT42) -> -742.01 | U42: -34.095 | Y42: -34.465 | AB42: -33.795 | AF42: -33.47 | AM42: -67.27 | AP42: -64.65 | BB42: -101.89 | BN42: -33.28 | BS42: -70.09 | BZ42: -67.36 | CF42: -101.49 | CL42: -33.56 | CR42: -66.595
...

Sheet ALÜMİNYUM STOK
B3: ALÜMİNYUM
B5: 0.3 | C5: 3.4
B6: 0.5 | C6: =21.6+20.86+3.44+17.62 -> 63.52
B7: 0.55 | C7: 10.46
B8: 1 | C8: 2.5
B9: 1.2 | C9: 16.4
B10: 1.3 | C10: 4.8
B11: 1.4 | C11: 9.14
B12: 1.6 | C12: 9.22
B13: 1.7 | C13: 18.5
B14: 1.8 | C14: 64.48
B15: 3.5 | C15: 52.36

Sheet STOK
A1: TEL | B1: CİNS | C1: RAF NO | D1: ELSAN | E1: HES | F1: ERİKOĞLU | G1: EMSAN | H1: KAVİ | I1: EMTEL | J1: TOPLAM
A2: 0,40 | B2: ÇIPLAK TEL | C2: 102 | I2: ='STOK DETAY'!D6 -> 25.675 | J2: =SUM(D2:I2) -> 25.675
A3: 0,50 | B3: ÇIPLAK TEL | C3: 102 | I3: ='STOK DETAY'!E6 -> 0 | J3: =SUM(D3:I3) -> 0
A4: 0,60 | B4: ÇIPLAK TEL | C4: 102 | I4: ='STOK DETAY'!F6 -> 0 | J4: =SUM(D4:I4) -> 0
A5: 2,60 | B5: ÇIPLAK TEL | I5: ='STOK DETAY'!G6 -> 0 | J5: =SUM(D5:I5) -> 0
A6: 0,10 | B6: HCO | C6: 312 | F6: ='STOK DETAY'!H6 -> 92.75 | J6: =SUM(D6:I6) -> 92.75
A7: 0,16 | B7: HCO | C7: 113 | F7: ='STOK DETAY'!I6 -> 38.11 | J7: =SUM(D7:I7) -> 38.11
A8: 0,20 | B8: HCO | C8: 103 | E8: ='STOK DETAY'!L6 -> 0 | F8: ='STOK DETAY'!M6 -> 0 | J8: =SUM(D8:I8) -> 0
A9: 0,25 | B9: HCO | C9: 103 | D9: ='STOK DETAY'!N6 -> 0 | E9: ='STOK DETAY'!O6 -> 8.615 | F9: ='STOK DETAY'!P6 -> 0 | H9: ='STOK DETAY'!Q6 -> 0 | I9: ='STOK DETAY'!R6 -> 0 | J9: =SUM(D9:I9) -> 8.615
A10: 0,28 | B10: HCI | F10: ='STOK DETAY'!S6 -> 93.21 | J10: =SUM(D10:I10) -> 93.21
A11: 0,30 | B11: HCO | C11: 201 | D11: ='STOK DETAY'!T6 -> 0 | E11: ='STOK DETAY'!U6 -> 0 | F11: ='STOK DETAY'!V6 -> 54.595 | I11: ='STOK DETAY'!W6 -> 0 | J11: =SUM(D11:I11) -> 54.595
A12: 0,35 | B12: HCO | C12: 201 | D12: ='STOK DETAY'!X6 -> 0 | E12: ='STOK DETAY'!Y6 -> 0 | F12: ='STOK DETAY'!Z6 -> 8.355 | J12: =SUM(D12:I12) -> 8.355
A13: 0,40 | B13: HCO | C13: 202 | D13: ='STOK DETAY'!AA6 -> 0 | E13: ='STOK DETAY'!AB6 -> 0 | F13: ='STOK DETAY'!AC6 -> 0 | I13: ='STOK DETAY'!AD6 -> 0 | J13: =SUM(D13:I13) -> 0
A14: 0,45 | B14: HCO | C14: 202 | D14: ='STOK DETAY'!AE6 -> 0 | E14: ='STOK DETAY'!AF6 -> 0 | F14: ='STOK DETAY'!AG6 -> 0 | G14: ='STOK DETAY'!AH6 -> 0 | H14: ='STOK DETAY'!AI6 -> 0 | I14: ='STOK DETAY'!AJ6 -> 0 | J14: =SUM(D14:I14) -> 0
A15: 0,475 | B15: HCO | F15: ='STOK DETAY'!AK6 -> 24.27 | J15: =SUM(D15:I15) -> 24.27
A16: 0,50 | B16: HCO | C16: 203 | D16: ='STOK DETAY'!AL6 -> 0 | E16: ='STOK DETAY'!AM6 -> 0 | F16: ='STOK DETAY'!AN6 -> 0 | H16: ='STOK DETAY'!AO6 -> 0 | J16: =SUM(D16:I16) -> 0
A17: 0,55 | B17: HCO | C17: 203 | D17: ='STOK DETAY'!AP6 -> 0 | E17: ='STOK DETAY'!AQ6 -> 0 | F17: ='STOK DETAY'!AR6 -> 0 | G17: ='STOK DETAY'!AS6 -> 0 | H17: ='STOK DETAY'!AT6 -> 0 | J17: =SUM(D17:I17) -> 0
A18: 0,60 | B18: HCO | C18: 301 | D18: ='STOK DETAY'!AU6 -> 0 | E18: ='STOK DETAY'!AV6 -> 0 | F18: ='STOK DETAY'!AW6 -> 0 | G18: ='STOK DETAY'!AX6 -> 0 | H18: ='STOK DETAY'!AY6 -> 0 | I18: ='STOK DETAY'!AZ6 -> 17 | J18: =SUM(D18:I18) -> 17
A19: 0,65 | B19: HCO | C19: 301 | D19: ='STOK DETAY'!BA6 -> 0 | E19: ='STOK DETAY'!BB6 -> 0 | F19: ='STOK DETAY'!BC6 -> 0 | H19: ='STOK DETAY'!BE6 -> 0 | I19: ='STOK DETAY'!BF6 -> 8.565 | J19: =SUM(D19:I19) -> 8.565
A20: 0,70 | B20: HCO | C20: 302 | D20: ='STOK DETAY'!BG6 -> 0 | E20: ='STOK DETAY'!BH6 -> 0 | F20: ='STOK DETAY'!BI6 -> 0 | G20: ='STOK DETAY'!BJ6 -> 0 | H20: ='STOK DETAY'!BK6 -> 0 | I20: ='STOK DETAY'!BL6 -> 34.685 | J20: =SUM(D20:I20) -> 34.685
A21: 0,75 | B21: HCO | C21: 302 | D21: ='STOK DETAY'!BM6 -> 0 | E21: ='STOK DETAY'!BN6 -> 0 | F21: ='STOK DETAY'!BO6 -> 0 | G21: ='STOK DETAY'!BP6 -> 0 | H21: ='STOK DETAY'!BQ6 -> 0 | I21: ='STOK DETAY'!BR6 -> 42.745 | J21: =SUM(D21:I21) -> 42.745
A22: 0,80 | B22: HCO | C22: 303 | D22: ='STOK DETAY'!BS6 -> 0 | E22: ='STOK DETAY'!BT6 -> 0 | F22: ='STOK DETAY'!BU6 -> 0 | G22: ='STOK DETAY'!BV6 -> 0 | H22: ='STOK DETAY'!BW6 -> 0 | I22: ='STOK DETAY'!BX6 -> 53.14 | J22: =SUM(D22:I22) -> 53.14
A23: 0,85 | B23: HCO | C23: 303 | D23: ='STOK DETAY'!BY6 -> 0 | E23: ='STOK DETAY'!BZ6 -> 0 | F23: ='STOK DETAY'!CA6 -> 0 | G23: ='STOK DETAY'!CB6 -> 0 | H23: ='STOK DETAY'!CC6 -> 0 | I23: ='STOK DETAY'!CD6 -> 49.975 | J23: =SUM(D23:I23) -> 49.975
A24: 0,90 | B24: HCO | C24: 401 | D24: ='STOK DETAY'!CE6 -> 0 | E24: ='STOK DETAY'!CF6 -> 0 | F24: ='STOK DETAY'!CG6 -> 0 | G24: ='STOK DETAY'!CH6 -> 0 | H24: ='STOK DETAY'!CI6 -> 0 | I24: ='STOK DETAY'!CJ6 -> 50.62 | J24: =SUM(D24:I24) -> 50.62
A25: 0,95 | B25: HCO | C25: 401 | D25: ='STOK DETAY'!CK6 -> 0 | E25: ='STOK DETAY'!CL6 -> 8.645 | F25: ='STOK DETAY'!CM6 -> 0 | G25: ='STOK DETAY'!CN6 -> 0 | H25: ='STOK DETAY'!CO6 -> 0 | I25: ='STOK DETAY'!CP6 -> 16.7 | J25: =SUM(D25:I25) -> 25.345
A26: 1,00 | B26: HCO | C26: 402 | D26: ='STOK DETAY'!CQ6 -> 0 | E26: ='STOK DETAY'!CR6 -> 0 | F26: ='STOK DETAY'!CS6 -> 24.93 | G26: ='STOK DETAY'!CT6 -> 0 | H26: ='STOK DETAY'!CU6 -> 0 | I26: ='STOK DETAY'!CV6 -> 0 | J26: =SUM(D26:I26) -> 24.93
A27: 1,05 | B27: HCO | C27: 402 | D27: ='STOK DETAY'!CW6 -> 0 | E27: ='STOK DETAY'!CX6 -> 0 | F27: ='STOK DETAY'!CY6 -> 0 | G27: ='STOK DETAY'!CZ6 -> 0 | H27: ='STOK DETAY'!DA6 -> 0 | I27: ='STOK DETAY'!DB6 -> 0 | J27: =SUM(D27:I27) -> 0
A28: 1,10 | B28: HCO | C28: 403 | D28: ='STOK DETAY'!DC6 -> 0 | E28: ='STOK DETAY'!DD6 -> 0 | F28: ='STOK DETAY'!DE6 -> 25.735 | G28: ='STOK DETAY'!DF6 -> 0 | H28: ='STOK DETAY'!DG6 -> 0 | J28: =SUM(D28:I28) -> 25.735
A29: 1,15 | B29: HCO | C29: 403 | D29: ='STOK DETAY'!DI6 -> 0 | E29: ='STOK DETAY'!DJ6 -> 0 | F29: ='STOK DETAY'!DK6 -> 0 | G29: ='STOK DETAY'!DL6 -> 0 | H29: ='STOK DETAY'!DM6 -> 0 | J29: =SUM(D29:I29) -> 0
A30: 1,20 | B30: HCO | C30: 501 | D30: ='STOK DETAY'!DN6 -> 0 | E30: ='STOK DETAY'!DO6 -> 8.525 | F30: ='STOK DETAY'!DP6 -> 8.805 | G30: ='STOK DETAY'!DQ6 -> 0 | H30: ='STOK DETAY'!DR6 -> 0 | J30: =SUM(D30:I30) -> 17.33
A31: 1,25 | B31: HCO | C31: 501 | D31: ='STOK DETAY'!DS6 -> 0 | E31: ='STOK DETAY'!DT6 -> 0 | F31: ='STOK DETAY'!DU6 -> 0 | G31: ='STOK DETAY'!DV6 -> 0 | H31: ='STOK DETAY'!DW6 -> 0 | I31: ='STOK DETAY'!DX6 -> 0 | J31: =SUM(D31:I31) -> 0
A32: 1,30 | B32: HCO | C32: 502 | D32: ='STOK DETAY'!DY6 -> 0 | E32: ='STOK DETAY'!DZ6 -> 0 | F32: ='STOK DETAY'!EA6 -> 8.38 | G32: ='STOK DETAY'!EB6 -> 0 | H32: ='STOK DETAY'!EC6 -> 0 | I32: ='STOK DETAY'!ED6 -> 0 | J32: =SUM(D32:I32) -> 8.38
A33: 1,35 | B33: HCO | C33: 502 | D33: ='STOK DETAY'!EE6 -> 0 | E33: ='STOK DETAY'!EF6 -> 0 | F33: ='STOK DETAY'!EG6 -> 378.33 | G33: ='STOK DETAY'!EH6 -> 1.75 | H33: ='STOK DETAY'!EI6 -> 8.44 | J33: =SUM(D33:I33) -> 388.52
A34: 1,40 | B34: HCO | C34: 503 | D34: ='STOK DETAY'!EJ6 -> 0 | E34: ='STOK DETAY'!EK6 -> 0 | F34: ='STOK DETAY'!EL6 -> 0 | H34: ='STOK DETAY'!EM6 -> 68.8 | J34: =SUM(D34:I34) -> 68.8
A35: 1,45 | B35: HCO | C35: 503 | D35: ='STOK DETAY'!EN6 -> 0 | E35: ='STOK DETAY'!EO6 -> 0 | F35: ='STOK DETAY'!EP6 -> 16.17 | H35: ='STOK DETAY'!EQ6 -> 0 | J35: =SUM(D35:I35) -> 16.17
A36: 1,50 | B36: HCO | D36: ='STOK DETAY'!ER6 -> 0 | E36: ='STOK DETAY'!ES6 -> 0 | F36: ='STOK DETAY'!ET6 -> 0 | H36: ='STOK DETAY'!EU6 -> 0 | J36: =SUM(D36:I36) -> 0
A37: 1,55 | B37: HCO | C37: 211 | H37: ='STOK DETAY'!EV6 -> 27.65 | J37: =SUM(D37:I37) -> 27.65
A38: 1,60 | B38: HCO | E38: ='STOK DETAY'!EW6 -> 0 | J38: =SUM(D38:I38) -> 0
A39: 1,70 | B39: HCO | E39: ='STOK DETAY'!EY6 -> 0 | F39: ='STOK DETAY'!EZ6 -> 0 | J39: =SUM(D39:I39) -> 0
A40: 1,80 | B40: HCO | D40: ='STOK DETAY'!FA6 -> 0 | E40: ='STOK DETAY'!FB6 -> 0 | F40: ='STOK DETAY'!FC6 -> 0 | H40: ='STOK DETAY'!FD6 -> 0 | J40: =SUM(D40:I40) -> 0
...
